Workbook

Sheet README
A1: Kiln Fuel Blending Model (FY2025) - Excel Solver version
A2: Simulation anchored to public data. Not FCCL's actual procurement plan; FCCL did not use or endorse this model.
A4: Colour legend
A5: Blue text = input (published, calculated in R/01_build_dataset.R, assumed or simulated - see cell notes and data/data_dictionary.csv)
A6: Black text = formula | Green text = link to another sheet | Yellow fill = decision variables Solver changes
A8: Sheets
A9: Inputs - fuel quality, capacities, prices, freight, heat demand, limits
A10: Model - decision variables (tonnes), objective (total cost) and every constraint
A11: Baseline - FY25 disclosed fuel mix applied at every plant (the comparison case)
A12: Results - baseline vs optimized, saving, allocation, shadow prices, R cross-check
A14: How to run Solver (Windows Excel)
A15: 1. File > Options > Add-ins > Manage Excel Add-ins > Go > tick Solver Add-in > OK.
... A24: No Excel? LibreOffice Calc: Tools > Solver, same settings, engine 'LibreOffice Linear Solver'.

Sheet Inputs
A1: Inputs - FY2025
A2: Sources and data types: references/sources.md and data/data_dictionary.csv. V = verified, C = calculated, A = assumption, S = simulated.
A4: Fuel sources
A5: ID | B5: Fuel | C5: Type | D5: NCV (GJ/t) | E5: Sulphur (%) | F5: Supply capacity (t/yr) | G5: Price at origin (Rs/t) | H5: Sulphur minus limit (coal only) | I5: Alt-fuel NCV (alt only) | J5: Data types
A6: AFG | B6: Afghan coal | C6: coal | D6: 25.121 | E6: 0.8 | F6: 200000 | G6: 37748 | H6: =IF(C6="coal",E6-$C$24,0) | I6: =IF(C6="alt_fuel",D6,0) | J6: NCV/sulphur V or C; capacity S; price C
A7: BAL | B7: Local coal - Balochistan | C7: coal | D7: 23.204 | E7: 4.9 | F7: 300000 | G7: 30123 | H7: =IF(C7="coal",E7-$C$24,0) | I7: =IF(C7="alt_fuel",D7,0) | J7: NCV/sulphur V or C; capacity S; price C
A8: SRC | B8: Local coal - Salt Range | C8: coal | D8: 18.735 | E8: 5.32 | F8: 300000 | G8: 24322 | H8: =IF(C8="coal",E8-$C$24,0) | I8: =IF(C8="alt_fuel",D8,0) | J8: NCV/sulphur V or C; capacity S; price C
A9: IMP | B9: Imported coal (South African type) | C9: coal | D9: 23.701 | E9: 0.8 | F9: 1000000 | G9: 34672 | H9: =IF(C9="coal",E9-$C$24,0) | I9: =IF(C9="alt_fuel",D9,0) | J9: NCV/sulphur V or C; capacity S; price C
A10: BIO | B10: Biomass (rice husk) | C10: alt_fuel | D10: 12.267 | E10: 0.11 | F10: 100000 | G10: 12000 | H10: =IF(C10="coal",E10-$C$24,0) | I10: =IF(C10="alt_fuel",D10,0) | J10: NCV/sulphur V or C; capacity S; price S
A11: TDF | B11: Tyre-derived fuel | C11: alt_fuel | D11: 35.15 | E11: 1.57 | F11: 15000 | G11: 20000 | H11: =IF(C11="coal",E11-$C$24,0) | I11: =IF(C11="alt_fuel",D11,0) | J11: NCV/sulphur V or C; capacity S; price S
A13: Plants
A14: ID | B14: Plant | C14: Capacity (t/day) | D14: Clinker (t) | E14: Heat demand (GJ)
A15: JB | B15: Jhang Bahtar | C15: 11865 | D15: 1565727 | E15: 4743342
A16: WAH | B16: Wah | C16: 3675 | D16: 484960 | E16: 1469178
A17: NZP | B17: Nizampur | C17: 12495 | D17: 1648863 | E17: 4995201
A18: DGK | B18: Dera Ghazi Khan | C18: 6825 | D18: 900639 | E18: 2728470
B19: Total | E19: =SUM(E15:E18)
A21: Parameters
A22: Parameter | C22: Value | D22: Unit | E22: Type / note
A23: Freight multiplier (scenario lever) | C23: 1 | D23: x | E23: A: 1.00 = base case; 1.25 = freight +25%
A24: Sulphur limit, coal blend | C24: =SUMPRODUCT(C30:C33,E6:E9) | D24: % | E24: C: baseline coal-blend sulphur (no dirtier than baseline)
A25: Max alt-fuel share of heat | C25: 0.15 | D25: fraction | E25: A: technical cap
A28: Baseline alt-fuel share of heat | C28: 0.094 | D28: fraction | E28: V: FY25 thermal substitution rate (S19)
A29: Baseline tyre share of alt-fuel heat | C29: 0.25982816 | D29: fraction | E29: C: calibrated to 88,727 t alt fuels (S19)
A30: Baseline coal share - Afghan | C30: 0.25 | D30: of coal mass | E30: V: FY25 25% Afghan (S7)
A31: Baseline coal share - Balochistan | C31: 0.375 | D31: of coal mass | E31: V 75% local (S7) x A 50% split
A32: Baseline coal share - Salt Range | C32: 0.375 | D32: of coal mass | E32: V 75% local (S7) x A 50% split
A33: Baseline coal share - Imported | C33: 0 | D33: of coal mass | E33: None imported in FY25 baseline
A35: Freight to plant (Rs/t) - road km x Rs 6.92/t-km, rounded (R/01_build_dataset.R)
A36: Fuel | B36: JB | C36: WAH | D36: NZP | E36: DGK
A37: AFG | B37: 1407 | C37: 1501 | D37: 850 | E37: 4104
A38: BAL | B38: 4857 | C38: 5101 | D38: 4672 | E38: 1792
A39: SRC | B39: 891 | C39: 1033 | D39: 1333 | E39: 3338
A40: IMP | B40: 9932 | C40: 10171 | D40: 9897 | E40: 6031
A41: BIO | B41: 0 | C41: 0 | D41: 0 | E41: 0
A42: TDF | B42: 0 | C42: 0 | D42: 0 | E42: 0
A44: Delivered cost (Rs/t) = price at origin + freight x multiplier -> objective coefficients
A45: Fuel | B45: JB | C45: WAH | D45: NZP | E45: DGK
A46: AFG | B46: =$G6+B37*$C$23 | C46: =$G6+C37*$C$23 | D46: =$G6+D37*$C$23 | E46: =$G6+E37*$C$23
A47: BAL | B47: =$G7+B38*$C$23 | C47: =$G7+C38*$C$23 | D47: =$G7+D38*$C$23 | E47: =$G7+E38*$C$23
...

Sheet Model
A1: Model - decision variables, objective, constraints
A2: Yellow cells B5:E10 = decision variables. They currently hold the optimum found in R; clear them and re-run Solver to reproduce.
A4: Tonnes delivered (t/yr) | B4: JB | C4: WAH | D4: NZP | E4: DGK | F4: Total used | G4: Capacity | H4: Spare
A5: =Inputs!B6 | B5: 55874.722 | C5: 17306.345 | D5: 54413.266 | E5: 23799.743 | F5: =SUM(B5:E5) | G5: =Inputs!F6 | H5: =G5-F5
A6: =Inputs!B7 | B6: 0 | C6: 0 | D6: 30200.208 | E6: 88683.193 | F6: =SUM(B6:E6) | G6: =Inputs!F7 | H6: =G6-F6
A7: =Inputs!B8 | B7: 140283.52 | C7: 43450.687 | D7: 116265.79 | E7: 0 | F7: =SUM(B7:E7) | G7: =Inputs!F8 | H7: =G7-F7
A8: =Inputs!B9 | B8: 0 | C8: 0 | D8: 0 | E8: 0 | F8: =SUM(B8:E8) | G8: =Inputs!F9 | H8: =G8-F8
A9: =Inputs!B10 | B9: 38919.039 | C9: 0 | D9: 61080.961 | E9: 0 | F9: =SUM(B9:E9) | G9: =Inputs!F10 | H9: =G9-F9
A10: =Inputs!B11 | B10: 6659.501 | C10: 6269.607 | D10: 0 | E10: 2070.892 | F10: =SUM(B10:E10) | G10: =Inputs!F11 | H10: =G10-F10
A12: Objective
A13: Total fuel cost (Rs/yr) | B13: =SUMPRODUCT(Inputs!$B$46:$E$51,B5:E10)
A14: Cost per GJ of kiln heat (Rs/GJ) | B14: =B13/Inputs!E19
A16: Constraints by plant | B16: JB | C16: WAH | D16: NZP | E16: DGK
A17: Heat supplied (GJ) [must be >= row 18] | B17: =SUMPRODUCT(Inputs!$D$6:$D$11,B5:B10) | C17: =SUMPRODUCT(Inputs!$D$6:$D$11,C5:C10) | D17: =SUMPRODUCT(Inputs!$D$6:$D$11,D5:D10) | E17: =SUMPRODUCT(Inputs!$D$6:$D$11,E5:E10)
A18: Heat demand (GJ) | B18: =Inputs!$E$15 | C18: =Inputs!$E$16 | D18: =Inputs!$E$17 | E18: =Inputs!$E$18
A19: Sulphur constraint value [must be <= 0] | B19: =SUMPRODUCT(Inputs!$H$6:$H$11,B5:B10) | C19: =SUMPRODUCT(Inputs!$H$6:$H$11,C5:C10) | D19: =SUMPRODUCT(Inputs!$H$6:$H$11,D5:D10) | E19: =SUMPRODUCT(Inputs!$H$6:$H$11,E5:E10)
A20: Coal-blend sulphur (%) | B20: =IFERROR(SUMPRODUCT(Inputs!$E$6:$E$9,B5:B8)/SUM(B5:B8),0) | C20: =IFERROR(SUMPRODUCT(Inputs!$E$6:$E$9,C5:C8)/SUM(C5:C8),0) | D20: =IFERROR(SUMPRODUCT(Inputs!$E$6:$E$9,D5:D8)/SUM(D5:D8),0) | E20: =IFERROR(SUMPRODUCT(Inputs!$E$6:$E$9,E5:E8)/SUM(E5:E8),0)
A21: Sulphur limit (%) | B21: =Inputs!$C$24 | C21: =Inputs!$C$24 | D21: =Inputs!$C$24 | E21: =Inputs!$C$24
A22: Alt-fuel constraint value [must be <= 0] | B22: =SUMPRODUCT(Inputs!$I$6:$I$11,B5:B10)-Inputs!$C$25*B17 | C22: =SUMPRODUCT(Inputs!$I$6:$I$11,C5:C10)-Inputs!$C$25*C17 | D22: =SUMPRODUCT(Inputs!$I$6:$I$11,D5:D10)-Inputs!$C$25*D17 | E22: =SUMPRODUCT(Inputs!$I$6:$I$11,E5:E10)-Inputs!$C$25*E17
A23: Alt-fuel share of heat | B23: =IFERROR(SUMPRODUCT(Inputs!$I$6:$I$11,B5:B10)/B17,0) | C23: =IFERROR(SUMPRODUCT(Inputs!$I$6:$I$11,C5:C10)/C17,0) | D23: =IFERROR(SUMPRODUCT(Inputs!$I$6:$I$11,D5:D10)/D17,0) | E23: =IFERROR(SUMPRODUCT(Inputs!$I$6:$I$11,E5:E10)/E17,0)
A24: Alt-fuel cap | B24: =Inputs!$C$25 | C24: =Inputs!$C$25 | D24: =Inputs!$C$25 | E24: =Inputs!$C$25
A25: All plant constraints met? | B25: =IF(AND(B17>=B18-1,B19<=1,B22<=1),"OK","CHECK") | C25: =IF(AND(C17>=C18-1,C19<=1,C22<=1),"OK","CHECK") | D25: =IF(AND(D17>=D18-1,D19<=1,D22<=1),"OK","CHECK") | E25: =IF(AND(E17>=E18-1,E19<=1,E22<=1),"OK","CHECK")
A26: All supply limits met? | B26: =IF(MIN(H5:H10)>=-1,"OK","CHECK")
A28: Cross-check with R (R/02_optimization_model.R)
A29: R optimum (Rs/yr) | B29: 18965941349
A30: Excel minus R (Rs/yr) | B30: =B13-B29
A31: Difference as % of R optimum | B31: =B30/B29
A32: R decision values are rounded to 0.001 t here, so a difference of a few rupees is expected.

Sheet Baseline
A1: Baseline - FY25 disclosed fuel mix applied at every plant
A2: Alt fuels give 9.4% of heat (tyres 26% of that heat, biomass the rest); coal is 25% Afghan / 37.5% Balochistan / 37.5% Salt Range by mass.
A4: Tonnes delivered (t/yr) | B4: JB | C4: WAH | D4: NZP | E4: DGK | F4: Total used | G4: Capacity | H4: Spare
A5: =Inputs!B6 | B5: =Inputs!$C$30*Inputs!$E$15*(1-Inputs!$C$28)/$H$13 | C5: =Inputs!$C$30*Inputs!$E$16*(1-Inputs!$C$28)/$H$13 | D5: =Inputs!$C$30*Inputs!$E$17*(1-Inputs!$C$28)/$H$13 | E5: =Inputs!$C$30*Inputs!$E$18*(1-Inputs!$C$28)/$H$13 | F5: =SUM(B5:E5) | G5: =Inputs!F6 | H5: =G5-F5
A6: =Inputs!B7 | B6: =Inputs!$C$31*Inputs!$E$15*(1-Inputs!$C$28)/$H$13 | C6: =Inputs!$C$31*Inputs!$E$16*(1-Inputs!$C$28)/$H$13 | D6: =Inputs!$C$31*Inputs!$E$17*(1-Inputs!$C$28)/$H$13 | E6: =Inputs!$C$31*Inputs!$E$18*(1-Inputs!$C$28)/$H$13 | F6: =SUM(B6:E6) | G6: =Inputs!F7 | H6: =G6-F6
A7: =Inputs!B8 | B7: =Inputs!$C$32*Inputs!$E$15*(1-Inputs!$C$28)/$H$13 | C7: =Inputs!$C$32*Inputs!$E$16*(1-Inputs!$C$28)/$H$13 | D7: =Inputs!$C$32*Inputs!$E$17*(1-Inputs!$C$28)/$H$13 | E7: =Inputs!$C$32*Inputs!$E$18*(1-Inputs!$C$28)/$H$13 | F7: =SUM(B7:E7) | G7: =Inputs!F8 | H7: =G7-F7
A8: =Inputs!B9 | B8: =Inputs!$C$33*Inputs!$E$15*(1-Inputs!$C$28)/$H$13 | C8: =Inputs!$C$33*Inputs!$E$16*(1-Inputs!$C$28)/$H$13 | D8: =Inputs!$C$33*Inputs!$E$17*(1-Inputs!$C$28)/$H$13 | E8: =Inputs!$C$33*Inputs!$E$18*(1-Inputs!$C$28)/$H$13 | F8: =SUM(B8:E8) | G8: =Inputs!F9 | H8: =G8-F8
A9: =Inputs!B10 | B9: =Inputs!$E$15*Inputs!$C$28*(1-Inputs!$C$29)/Inputs!$D$10 | C9: =Inputs!$E$16*Inputs!$C$28*(1-Inputs!$C$29)/Inputs!$D$10 | D9: =Inputs!$E$17*Inputs!$C$28*(1-Inputs!$C$29)/Inputs!$D$10 | E9: =Inputs!$E$18*Inputs!$C$28*(1-Inputs!$C$29)/Inputs!$D$10 | F9: =SUM(B9:E9) | G9: =Inputs!F10 | H9: =G9-F9
A10: =Inputs!B11 | B10: =Inputs!$E$15*Inputs!$C$28*Inputs!$C$29/Inputs!$D$11 | C10: =Inputs!$E$16*Inputs!$C$28*Inputs!$C$29/Inputs!$D$11 | D10: =Inputs!$E$17*Inputs!$C$28*Inputs!$C$29/Inputs!$D$11 | E10: =Inputs!$E$18*Inputs!$C$28*Inputs!$C$29/Inputs!$D$11 | F10: =SUM(B10:E10) | G10: =Inputs!F11 | H10: =G10-F10
A12: Objective
A13: Total fuel cost (Rs/yr) | B13: =SUMPRODUCT(Inputs!$B$46:$E$51,B5:E10) | G13: Coal-mix NCV (GJ/t) | H13: =SUMPRODUCT(Inputs!$C$30:$C$33,Inputs!$D$6:$D$9)
A14: Cost per GJ of kiln heat (Rs/GJ) | B14: =B13/Inputs!E19
A16: Constraints by plant | B16: JB | C16: WAH | D16: NZP | E16: DGK
A17: Heat supplied (GJ) [must be >= row 18] | B17: =SUMPRODUCT(Inputs!$D$6:$D$11,B5:B10) | C17: =SUMPRODUCT(Inputs!$D$6:$D$11,C5:C10) | D17: =SUMPRODUCT(Inputs!$D$6:$D$11,D5:D10) | E17: =SUMPRODUCT(Inputs!$D$6:$D$11,E5:E10)
A18: Heat demand (GJ) | B18: =Inputs!$E$15 | C18: =Inputs!$E$16 | D18: =Inputs!$E$17 | E18: =Inputs!$E$18
A19: Sulphur constraint value [must be <= 0] | B19: =SUMPRODUCT(Inputs!$H$6:$H$11,B5:B10) | C19: =SUMPRODUCT(Inputs!$H$6:$H$11,C5:C10) | D19: =SUMPRODUCT(Inputs!$H$6:$H$11,D5:D10) | E19: =SUMPRODUCT(Inputs!$H$6:$H$11,E5:E10)
A20: Coal-blend sulphur (%) | B20: =IFERROR(SUMPRODUCT(Inputs!$E$6:$E$9,B5:B8)/SUM(B5:B8),0) | C20: =IFERROR(SUMPRODUCT(Inputs!$E$6:$E$9,C5:C8)/SUM(C5:C8),0) | D20: =IFERROR(SUMPRODUCT(Inputs!$E$6:$E$9,D5:D8)/SUM(D5:D8),0) | E20: =IFERROR(SUMPRODUCT(Inputs!$E$6:$E$9,E5:E8)/SUM(E5:E8),0)
A21: Sulphur limit (%) | B21: =Inputs!$C$24 | C21: =Inputs!$C$24 | D21: =Inputs!$C$24 | E21: =Inputs!$C$24
A22: Alt-fuel constraint value [must be <= 0] | B22: =SUMPRODUCT(Inputs!$I$6:$I$11,B5:B10)-Inputs!$C$25*B17 | C22: =SUMPRODUCT(Inputs!$I$6:$I$11,C5:C10)-Inputs!$C$25*C17 | D22: =SUMPRODUCT(Inputs!$I$6:$I$11,D5:D10)-Inputs!$C$25*D17 | E22: =SUMPRODUCT(Inputs!$I$6:$I$11,E5:E10)-Inputs!$C$25*E17
A23: Alt-fuel share of heat | B23: =IFERROR(SUMPRODUCT(Inputs!$I$6:$I$11,B5:B10)/B17,0) | C23: =IFERROR(SUMPRODUCT(Inputs!$I$6:$I$11,C5:C10)/C17,0) | D23: =IFERROR(SUMPRODUCT(Inputs!$I$6:$I$11,D5:D10)/D17,0) | E23: =IFERROR(SUMPRODUCT(Inputs!$I$6:$I$11,E5:E10)/E17,0)
A24: Alt-fuel cap | B24: =Inputs!$C$25 | C24: =Inputs!$C$25 | D24: =Inputs!$C$25 | E24: =Inputs!$C$25
A25: All plant constraints met? | B25: =IF(AND(B17>=B18-1,B19<=1,B22<=1),"OK","CHECK") | C25: =IF(AND(C17>=C18-1,C19<=1,C22<=1),"OK","CHECK") | D25: =IF(AND(D17>=D18-1,D19<=1,D22<=1),"OK","CHECK") | E25: =IF(AND(E17>=E18-1,E19<=1,E22<=1),"OK","CHECK")
A26: All supply limits met? | B26: =IF(MIN(H5:H10)>=-1,"OK","CHECK")

Sheet Results
A1: Results - baseline vs optimized (FY2025 simulation)
A2: Savings are measured against a rule-based baseline, not against FCCL's actual purchasing.
A4: Measure | B4: Baseline | C4: Optimized | D4: Difference | E4: % change
A5: Total fuel cost (Rs/yr) | B5: =Baseline!B13 | C5: =Model!B13 | D5: =C5-B5 | E5: =D5/B5
A6: Cost per GJ of kiln heat (Rs/GJ) | B6: =Baseline!B14 | C6: =Model!B14 | D6: =C6-B6 | E6: =D6/B6
A7: Cost reduction (%) = (Baseline - Optimized) / Baseline | B7: =(B5-C5)/B5
A9: Where the saving comes from (R, results/summary.json)
A10: Reallocating coal only (alt fuels fixed at baseline) | B10: 471956781 | C10: =B10/$B$5
A11: Using more alternative fuel | B11: 321755461 | C11: =B11/$B$5
A12: Total | B12: =B10+B11 | C12: =B12/$B$5
A14: Fuel | B14: Baseline (t) | C14: Optimized (t) | D14: Change (t) | E14: Supply capacity (t)
A15: =Inputs!B6 | B15: =Baseline!F5 | C15: =Model!F5 | D15: =C15-B15 | E15: =Inputs!F6
A16: =Inputs!B7 | B16: =Baseline!F6 | C16: =Model!F6 | D16: =C16-B16 | E16: =Inputs!F7
A17: =Inputs!B8 | B17: =Baseline!F7 | C17: =Model!F7 | D17: =C17-B17 | E17: =Inputs!F8
A18: =Inputs!B9 | B18: =Baseline!F8 | C18: =Model!F8 | D18: =C18-B18 | E18: =Inputs!F9
A19: =Inputs!B10 | B19: =Baseline!F9 | C19: =Model!F9 | D19: =C19-B19 | E19: =Inputs!F10
A20: =Inputs!B11 | B20: =Baseline!F10 | C20: =Model!F10 | D20: =C20-B20 | E20: =Inputs!F11
A22: Shadow prices (R lpSolve; Excel gives the same in Solver's Sensitivity Report)
A23: Constraint | B23: Shadow price | C23: Unit | F23: Meaning
A24: heat - JB | B24: 1491.28 | C24: Rs per GJ | F24: Cost of one more GJ of heat at this plant
A25: sulphur - JB | B25: -454.39 | C25: Rs per %-tonne | F25: Cost change if the sulphur limit were loosened by one %-tonne
A26: altfuel - JB | B26: -59.35 | C26: Rs per GJ | F26: Cost change if the alt-fuel cap were loosened by one GJ (negative = saving)
A27: heat - WAH | B27: 1496.59 | C27: Rs per GJ | F27: Cost of one more GJ of heat at this plant
A28: sulphur - WAH | B28: -434.95 | C28: Rs per %-tonne | F28: Cost change if the sulphur limit were loosened by one %-tonne
A29: altfuel - WAH | B29: -65.6 | C29: Rs per GJ | F29: Cost change if the alt-fuel cap were loosened by one GJ (negative = saving)
A30: heat - NZP | B30: 1497.79 | C30: Rs per GJ | F30: Cost of one more GJ of heat at this plant
A31: sulphur - NZP | B31: -222.55 | C31: Rs per %-tonne | F31: Cost change if the sulphur limit were loosened by one %-tonne
A32: altfuel - NZP | B32: -67.01 | C32: Rs per GJ | F32: Cost change if the alt-fuel cap were loosened by one GJ (negative = saving)
A33: heat - DGK | B33: 1440.83 | C33: Rs per GJ | F33: Cost of one more GJ of heat at this plant
A34: sulphur - DGK | B34: -1749.98 | C34: Rs per %-tonne | F34: Cost change if the sulphur limit were loosened by one %-tonne
A35: supply - SRC | B35: -2307.96 | C35: Rs per t | F35: Cost change if this source could supply one more tonne (negative = saving)
... A37: supply - TDF | B37: -30645.31 | C37: Rs per t | F37: Cost change if this source could supply one more tonne (negative = saving)
